[2022-08-03 16:30:46,830] {taskinstance.py:1179} INFO - Dependencies all met for <TaskInstance: ltv-pipeline.load-data manual__2022-08-03T16:30:12+00:00 [queued]>
[2022-08-03 16:30:46,869] {taskinstance.py:1179} INFO - Dependencies all met for <TaskInstance: ltv-pipeline.load-data manual__2022-08-03T16:30:12+00:00 [queued]>
[2022-08-03 16:30:46,879] {taskinstance.py:1376} INFO - 
--------------------------------------------------------------------------------
[2022-08-03 16:30:46,901] {taskinstance.py:1377} INFO - Starting attempt 1 of 1
[2022-08-03 16:30:46,938] {taskinstance.py:1378} INFO - 
--------------------------------------------------------------------------------
[2022-08-03 16:30:46,997] {taskinstance.py:1397} INFO - Executing <Task(PythonOperator): load-data> on 2022-08-03 16:30:12+00:00
[2022-08-03 16:30:47,129] {standard_task_runner.py:52} INFO - Started process 1391 to run task
[2022-08-03 16:30:47,170] {standard_task_runner.py:79} INFO - Running: ['***', 'tasks', 'run', 'ltv-pipeline', 'load-data', 'manual__2022-08-03T16:30:12+00:00', '--job-id', '71', '--raw', '--subdir', 'DAGS_FOLDER/dag-test.py', '--cfg-path', '/tmp/tmpj0ypfynj', '--error-file', '/tmp/tmpsvxvhaib']
[2022-08-03 16:30:47,196] {standard_task_runner.py:80} INFO - Job 71: Subtask load-data
[2022-08-03 16:30:47,727] {task_command.py:371} INFO - Running <TaskInstance: ltv-pipeline.load-data manual__2022-08-03T16:30:12+00:00 [running]> on host 3b0f05b8acbc
[2022-08-03 16:30:48,424] {taskinstance.py:1591} INFO - Exporting the following env vars:
AIRFLOW_CTX_DAG_OWNER=***
AIRFLOW_CTX_DAG_ID=ltv-pipeline
AIRFLOW_CTX_TASK_ID=load-data
AIRFLOW_CTX_EXECUTION_DATE=2022-08-03T16:30:12+00:00
AIRFLOW_CTX_TRY_NUMBER=1
AIRFLOW_CTX_DAG_RUN_ID=manual__2022-08-03T16:30:12+00:00
[2022-08-03 16:30:48,508] {taskinstance.py:1909} ERROR - Task failed with exception
Traceback (most recent call last):
  File "/home/airflow/.local/lib/python3.7/site-packages/airflow/operators/python.py", line 171, in execute
    return_value = self.execute_callable()
  File "/home/airflow/.local/lib/python3.7/site-packages/airflow/operators/python.py", line 189, in execute_callable
    return self.python_callable(*self.op_args, **self.op_kwargs)
  File "/opt/airflow/dags/dag-test.py", line 54, in insert_data
    post_hook.expert_copy("COPY logs FROM STDIN WITH DELIMITER ',' CSV HEADER ",f)
AttributeError: 'PostgresHook' object has no attribute 'expert_copy'
[2022-08-03 16:30:48,634] {taskinstance.py:1420} INFO - Marking task as FAILED. dag_id=ltv-pipeline, task_id=load-data, execution_date=20220803T163012, start_date=20220803T163046, end_date=20220803T163048
[2022-08-03 16:30:48,766] {standard_task_runner.py:97} ERROR - Failed to execute job 71 for task load-data ('PostgresHook' object has no attribute 'expert_copy'; 1391)
[2022-08-03 16:30:49,295] {local_task_job.py:156} INFO - Task exited with return code 1
[2022-08-03 16:30:51,684] {local_task_job.py:273} INFO - 0 downstream tasks scheduled from follow-on schedule check
